Workbook

Sheet in
A1: Claim ID | B1: Date Submitted | C1: Month | D1: Region | E1: Claim Type | F1: Claim Amount | G1: Status | H1: Processing Time (Days)
A2: C001 | B2: 14/05/2025 | C2: =TEXT(B2,"mmm") -> May | D2: East | E2: Auto | F2: 1349.16 | G2: Rejected | H2: 2
A3: C002 | B3: 17/10/2025 | C3: =TEXT(B3,"mmm") -> Oct | D3: East | E3: Travel | F3: 4436.26 | G3: Approved | H3: 1
A4: C003 | B4: 45757 | C4: =TEXT(B4,"mmm") -> Apr | D4: East | E4: Auto | F4: 3315.76 | G4: Rejected | H4: 9
A5: C004 | B5: 45758 | C5: =TEXT(B5,"mmm") -> Apr | D5: South | E5: Auto | F5: 1370.42 | G5: Approved | H5: 6
A6: C005 | B6: 45660 | C6: =TEXT(B6,"mmm") -> Jan | D6: West | E6: Auto | F6: 620.05 | G6: Approved | H6: 12
A7: C006 | B7: 28/09/2025 | C7: =TEXT(B7,"mmm") -> Sep | D7: South | E7: Auto | F7: 3066.87 | G7: Approved | H7: 4
A8: C007 | B8: 23/05/2025 | C8: =TEXT(B8,"mmm") -> May | D8: South | E8: Travel | F8: 2580.81 | G8: Pending | H8: 8
A9: C008 | B9: 16/10/2025 | C9: =TEXT(B9,"mmm") -> Oct | D9: West | E9: Home | F9: 4423.58 | G9: Rejected | H9: 4
A10: C009 | B10: 45839 | C10: =TEXT(B10,"mmm") -> Jul | D10: North | E10: Travel | F10: 3286.07 | G10: Rejected | H10: 11
A11: C010 | B11: 29/05/2025 | C11: =TEXT(B11,"mmm") -> May | D11: North | E11: Auto | F11: 3126.98 | G11: Pending | H11: 15
A12: C011 | B12: 45809 | C12: =TEXT(B12,"mmm") -> Jun | D12: West | E12: Auto | F12: 1774.42 | G12: Pending | H12: 1
A13: C012 | B13: 31/01/2025 | C13: =TEXT(B13,"mmm") -> Jan | D13: South | E13: Home | F13: 4329.48 | G13: Rejected | H13: 13
A14: C013 | B14: 25/11/2025 | C14: =TEXT(B14,"mmm") -> Nov | D14: South | E14: Travel | F14: 2985.41 | G14: Approved | H14: 8
A15: C014 | B15: 23/01/2025 | C15: =TEXT(B15,"mmm") -> Jan | D15: South | E15: Travel | F15: 1727.01 | G15: Approved | H15: 11
A16: C015 | B16: 20/08/2025 | C16: =TEXT(B16,"mmm") -> Aug | D16: East | E16: Health | F16: 820.25 | G16: Pending | H16: 13
A17: C016 | B17: 19/08/2025 | C17: =TEXT(B17,"mmm") -> Aug | D17: South | E17: Travel | F17: 2531.18 | G17: Pending | H17: 1
A18: C017 | B18: 20/12/2025 | C18: =TEXT(B18,"mmm") -> Dec | D18: West | E18: Home | F18: 4800.49 | G18: Pending | H18: 5
A19: C018 | B19: 13/06/2025 | C19: =TEXT(B19,"mmm") -> Jun | D19: South | E19: Health | F19: 3408.33 | G19: Pending | H19: 2
A20: C019 | B20: 20/10/2025 | C20: =TEXT(B20,"mmm") -> Oct | D20: South | E20: Home | F20: 2190.94 | G20: Rejected | H20: 11
A21: C020 | B21: 19/02/2025 | C21: =TEXT(B21,"mmm") -> Feb | D21: North | E21: Travel | F21: 4436.44 | G21: Rejected | H21: 11
A22: C021 | B22: 45780 | C22: =TEXT(B22,"mmm") -> May | D22: West | E22: Home | F22: 1052.89 | G22: Approved | H22: 2
A23: C022 | B23: 29/08/2025 | C23: =TEXT(B23,"mmm") -> Aug | D23: East | E23: Health | F23: 4122.76 | G23: Pending | H23: 13
A24: C023 | B24: 45968 | C24: =TEXT(B24,"mmm") -> Nov | D24: East | E24: Travel | F24: 4865.97 | G24: Pending | H24: 2
A25: C024 | B25: 29/01/2025 | C25: =TEXT(B25,"mmm") -> Jan | D25: South | E25: Home | F25: 4820.64 | G25: Rejected | H25: 13
A26: C025 | B26: 15/02/2025 | C26: =TEXT(B26,"mmm") -> Feb | D26: West | E26: Auto | F26: 1230.47 | G26: Pending | H26: 3
A27: C026 | B27: 23/03/2025 | C27: =TEXT(B27,"mmm") -> Mar | D27: West | E27: Home | F27: 3460.61 | G27: Approved | H27: 14
A28: C027 | B28: 23/08/2025 | C28: =TEXT(B28,"mmm") -> Aug | D28: South | E28: Travel | F28: 786.18 | G28: Pending | H28: 7
A29: C028 | B29: 31/05/2025 | C29: =TEXT(B29,"mmm") -> May | D29: East | E29: Auto | F29: 2327.45 | G29: Pending | H29: 3
A30: C029 | B30: 24/03/2025 | C30: =TEXT(B30,"mmm") -> Mar | D30: West | E30: Auto | F30: 2045.7 | G30: Pending | H30: 6
A31: C030 | B31: 45666 | C31: =TEXT(B31,"mmm") -> Jan | D31: West | E31: Home | F31: 3599.7 | G31: Pending | H31: 3
A32: C031 | B32: 45820 | C32: =TEXT(B32,"mmm") -> Jun | D32: West | E32: Health | F32: 4771.35 | G32: Rejected | H32: 12
A33: C032 | B33: 45871 | C33: =TEXT(B33,"mmm") -> Aug | D33: West | E33: Home | F33: 2331.45 | G33: Approved | H33: 14
A34: C033 | B34: 45752 | C34: =TEXT(B34,"mmm") -> Apr | D34: West | E34: Home | F34: 2620.93 | G34: Pending | H34: 9
A35: C034 | B35: 28/01/2025 | C35: =TEXT(B35,"mmm") -> Jan | D35: North | E35: Health | F35: 1289.26 | G35: Rejected | H35: 1
A36: C035 | B36: 45659 | C36: =TEXT(B36,"mmm") -> Jan | D36: North | E36: Auto | F36: 4224.64 | G36: Approved | H36: 11
A37: C036 | B37: 45846 | C37: =TEXT(B37,"mmm") -> Jul | D37: South | E37: Auto | F37: 3407.28 | G37: Approved | H37: 12
A38: C037 | B38: 45848 | C38: =TEXT(B38,"mmm") -> Jul | D38: West | E38: Travel | F38: 3197.56 | G38: Approved | H38: 5
A39: C038 | B39: 28/07/2025 | C39: =TEXT(B39,"mmm") -> Jul | D39: East | E39: Home | F39: 2798.99 | G39: Rejected | H39: 8
A40: C039 | B40: 31/03/2025 | C40: =TEXT(B40,"mmm") -> Mar | D40: South | E40: Health | F40: 2509.34 | G40: Rejected | H40: 7
...

Sheet Dashboard
B1: Insurance Claims Dashboard
B4: TOTAL CLAIMS | D4: APPROVED CLAIMS | F4: TOTAL CLAIM AMOUNT | I4: APPROVAL % | K4: REJECTION % | M4: AVG PROCESSING TIME
B5: =COUNTA(in!A2:A201) -> 200 | D5: =COUNTIF(in!G2:G201,"Approved") -> 66 | F5: =SUM(in!F2:F201) -> 552847.8 | I5: =D5/B5 -> 0.33 | K5: =1-I5 -> 0.67 | M5: =AVERAGE(in!H2:H201) -> 8.08
V6: Avg Processing Time by Region | AA6: Claim by Region
V7: Region | X7: Avg Processing Time | AA7: Region | AB7: Count | AC7: Total Amount
V8: North | X8: =AVERAGEIFS(in!H2:H201,in!D2:D201,"North") -> 8.2142857 | Z8: S | AA8: North | AB8: =COUNTIF(in!D2:D201,"North") -> 56 | AC8: =SUMIFS(in!F2:F201,in!D2:D201,"North") -> 150657.21
V9: South | X9: =AVERAGEIFS(in!H2:H201,in!D2:D201,"South") -> 7.975 | AA9: South | AB9: =COUNTIF(in!D2:D201,"South") -> 40 | AC9: =SUMIFS(in!F2:F201,in!D2:D201,"South") -> 101784.05
V10: East | X10: =AVERAGEIFS(in!H2:H201,in!D2:D201,"East") -> 8.0185185 | AA10: East | AB10: =COUNTIF(in!D2:D201,"East") -> 54 | AC10: =SUMIFS(in!F2:F201,in!D2:D201,"East") -> 154569.4
V11: West | X11: =AVERAGEIFS(in!H2:H201,in!D2:D201,"West") -> 8.08 | AA11: West | AB11: =COUNTIF(in!D2:D201,"West") -> 50 | AC11: =SUMIFS(in!F2:F201,in!D2:D201,"West") -> 145837.14
A12: *Highest claim month: July *Slowest processing region: North *Highest claim type: Home | AA12: Claim by Type
V13: Monthly Claim | AA13: Claim Type | AB13: Count | AC13: Total Amount
V14: Month | W14: Total Claims | X14: Total Amount | AA14: Health | AB14: =COUNTIF(in!E2:E201,"Health") -> 47 | AC14: =SUMIFS(in!F2:F201,in!E2:E201,"Health") -> 131224.86
V15: Jan | W15: =COUNTIF(in!C2:C201,"Jan") -> 16 | X15: =SUMIFS(in!F2:F201,in!C2:C201,"Jan") -> 48150.46 | AA15: Auto | AB15: =COUNTIF(in!E2:E201,"Auto") -> 51 | AC15: =SUMIFS(in!F2:F201,in!E2:E201,"Auto") -> 124552.07
V16: Feb | W16: =COUNTIF(in!C2:C201,"Feb") -> 17 | X16: =SUMIFS(in!F2:F201,in!C2:C201,"Feb") -> 40449.89 | AA16: Home | AB16: =COUNTIF(in!E2:E201,"Home") -> 52 | AC16: =SUMIFS(in!F2:F201,in!E2:E201,"Home") -> 156024.67
V17: Mar | W17: =COUNTIF(in!C2:C201,"Mar") -> 22 | X17: =SUMIFS(in!F2:F201,in!C2:C201,"Mar") -> 60236.98 | AA17: Travel | AB17: =COUNTIF(in!E2:E201,"Travel") -> 50 | AC17: =SUMIFS(in!F2:F201,in!E2:E201,"Travel") -> 141046.2
V18: Apr | W18: =COUNTIF(in!C3:C202,"Apr") -> 16 | X18: =SUMIFS(in!F2:F201,in!C2:C201,"Apr") -> 41719.31
V19: May | W19: =COUNTIF(in!C2:C201,"May") -> 20 | X19: =SUMIFS(in!F2:F201,in!C2:C201,"May") -> 55802.19
V20: Jun | W20: =COUNTIF(in!C2:C201,"Jun") -> 15 | X20: =SUMIFS(in!F2:F201,in!C2:C201,"Jun") -> 47780.13
V21: Jul | W21: =COUNTIF(in!C2:C201,"Jul") -> 27 | X21: =SUMIFS(in!F2:F201,in!C2:C201,"Jul") -> 81611.61
V22: Aug | W22: =COUNTIF(in!C2:C201,"Aug") -> 15 | X22: =SUMIFS(in!F2:F201,in!C2:C201,"Aug") -> 28134.65
V23: Sep | W23: =COUNTIF(in!C2:C201,"Sep") -> 14 | X23: =SUMIFS(in!F2:F201,in!C2:C201,"Sep") -> 38951.85
V24: Oct | W24: =COUNTIF(in!C2:C201,"Oct") -> 18 | X24: =SUMIFS(in!F2:F201,in!C2:C201,"Oct") -> 52678.93
V25: Nov | W25: =COUNTIF(in!C2:C201,"Nov") -> 9 | X25: =SUMIFS(in!F2:F201,in!C2:C201,"Nov") -> 28602.18
V26: Dec | W26: =COUNTIF(in!C2:C201,"Dec") -> 11 | X26: =SUMIFS(in!F2:F201,in!C2:C201,"Dec") -> 28729.62
Q45: g
